2023-01-26 09:28:02,477 - ERROR - asyncio - unhandled exception during asyncio.run() shutdown
task: <Task finished name='Task-1' coro=<_run_app() done, defined at C:\Users\R\PycharmProjects\fastapi_admin\venv\Lib\site-packages\aiohttp\web.py:289> exception=TelegramBadRequest('Bad Request: bad webhook: An HTTPS URL must be provided for webhook')>
Traceback (most recent call last):
  File "C:\Users\R\PycharmProjects\fastapi_admin\venv\Lib\site-packages\aiohttp\web.py", line 516, in run_app
    loop.run_until_complete(main_task)
  File "C:\Program Files\WindowsApps\PythonSoftwareFoundation.Python.3.11_3.11.496.0_x64__qbz5n2kfra8p0\Lib\asyncio\base_events.py", line 653, in run_until_complete
    return future.result()
           ^^^^^^^^^^^^^^^
  File "C:\Users\R\PycharmProjects\fastapi_admin\venv\Lib\site-packages\aiohttp\web.py", line 323, in _run_app
    await runner.setup()
  File "C:\Users\R\PycharmProjects\fastapi_admin\venv\Lib\site-packages\aiohttp\web_runner.py", line 279, in setup
    self._server = await self._make_server()
                   ^^^^^^^^^^^^^^^^^^^^^^^^^
  File "C:\Users\R\PycharmProjects\fastapi_admin\venv\Lib\site-packages\aiohttp\web_runner.py", line 375, in _make_server
    await self._app.startup()
  File "C:\Users\R\PycharmProjects\fastapi_admin\venv\Lib\site-packages\aiohttp\web_app.py", line 417, in startup
    await self.on_startup.send(self)
  File "C:\Users\R\PycharmProjects\fastapi_admin\venv\Lib\site-packages\aiosignal\__init__.py", line 36, in send
    await receiver(*args, **kwargs)  # type: ignore
    ^^^^^^^^^^^^^^^^^^^^^^^^^^^^^^^
  File "C:\Users\R\PycharmProjects\fastapi_admin\venv\Lib\site-packages\aiogram\webhook\aiohttp_server.py", line 33, in on_startup
    await dispatcher.emit_startup(**workflow_data)
  File "C:\Users\R\PycharmProjects\fastapi_admin\venv\Lib\site-packages\aiogram\dispatcher\router.py", line 205, in emit_startup
    await self.startup.trigger(*args, **kwargs)
  File "C:\Users\R\PycharmProjects\fastapi_admin\venv\Lib\site-packages\aiogram\dispatcher\event\event.py", line 41, in trigger
    await handler.call(*args, **kwargs)
  File "C:\Users\R\PycharmProjects\fastapi_admin\venv\Lib\site-packages\aiogram\dispatcher\event\handler.py", line 42, in call
    return await wrapped()
           ^^^^^^^^^^^^^^^
  File "C:\Users\R\PycharmProjects\fastapi_admin\src\app\modules\bot\bot_main.py", line 35, in on_startup
    await bot.set_webhook(f"{base_url}/webhook")
  File "C:\Users\R\PycharmProjects\fastapi_admin\venv\Lib\site-packages\aiogram\client\bot.py", line 469, in set_webhook
    return await self(call, request_timeout=request_timeout)
           ^^^^^^^^^^^^^^^^^^^^^^^^^^^^^^^^^^^^^^^^^^^^^^^^^
  File "C:\Users\R\PycharmProjects\fastapi_admin\venv\Lib\site-packages\aiogram\client\bot.py", line 364, in __call__
    return await self.session(self, method, timeout=request_timeout)
           ^^^^^^^^^^^^^^^^^^^^^^^^^^^^^^^^^^^^^^^^^^^^^^^^^^^^^^^^^
  File "C:\Users\R\PycharmProjects\fastapi_admin\venv\Lib\site-packages\aiogram\client\session\base.py", line 182, in __call__
    return cast(TelegramType, await middleware(bot, method))
                              ^^^^^^^^^^^^^^^^^^^^^^^^^^^^^
  File "C:\Users\R\PycharmProjects\fastapi_admin\venv\Lib\site-packages\aiogram\client\session\aiohttp.py", line 157, in make_request
    response = self.check_response(method=method, status_code=resp.status, content=raw_result)
               ^^^^^^^^^^^^^^^^^^^^^^^^^^^^^^^^^^^^^^^^^^^^^^^^^^^^^^^^^^^^^^^^^^^^^^^^^^^^^^^
  File "C:\Users\R\PycharmProjects\fastapi_admin\venv\Lib\site-packages\aiogram\client\session\base.py", line 100, in check_response
    raise TelegramBadRequest(method=method, message=description)
aiogram.exceptions.TelegramBadRequest: Bad Request: bad webhook: An HTTPS URL must be provided for webhook
2023-01-26 09:28:02,560 - ERROR - asyncio - Unclosed client session
client_session: <aiohttp.client.ClientSession object at 0x0000028EB0FEE490>
2023-01-26 09:28:02,561 - ERROR - asyncio - Unclosed connector
connections: ['[(<aiohttp.client_proto.ResponseHandler object at 0x0000028EB1118AD0>, 266688.093)]']
connector: <aiohttp.connector.TCPConnector object at 0x0000028EB1038650>
2023-01-26 09:34:45,264 - INFO - aiohttp.access - 127.0.0.1 [26/Jan/2023:06:34:45 +0000] "GET / HTTP/1.1" 404 173 "-" "Mozilla/5.0 (Windows NT 10.0; Win64; x64) AppleWebKit/537.36 (KHTML, like Gecko) Chrome/109.0.0.0 Safari/537.36"
2023-01-26 09:34:45,603 - INFO - aiohttp.access - 127.0.0.1 [26/Jan/2023:06:34:45 +0000] "GET /favicon.ico HTTP/1.1" 404 173 "http://127.0.0.1:8081/" "Mozilla/5.0 (Windows NT 10.0; Win64; x64) AppleWebKit/537.36 (KHTML, like Gecko) Chrome/109.0.0.0 Safari/537.36"
2023-01-26 09:34:54,000 - ERROR - aiohttp.server - Unhandled exception
Traceback (most recent call last):
  File "C:\Users\R\PycharmProjects\fastapi_admin\venv\Lib\site-packages\aiohttp\web_protocol.py", line 512, in start
    resp, reset = await task
                  ^^^^^^^^^^
  File "C:\Users\R\PycharmProjects\fastapi_admin\venv\Lib\site-packages\aiohttp\web_protocol.py", line 458, in _handle_request
    reset = await self.finish_response(request, resp, start_time)
            ^^^^^^^^^^^^^^^^^^^^^^^^^^^^^^^^^^^^^^^^^^^^^^^^^^^^^
  File "C:\Users\R\PycharmProjects\fastapi_admin\venv\Lib\site-packages\aiohttp\web_protocol.py", line 611, in finish_response
    await prepare_meth(request)
  File "C:\Users\R\PycharmProjects\fastapi_admin\venv\Lib\site-packages\aiohttp\web_fileresponse.py", line 142, in prepare
    st: os.stat_result = await loop.run_in_executor(None, filepath.stat)
                         ^^^^^^^^^^^^^^^^^^^^^^^^^^^^^^^^^^^^^^^^^^^^^^^
  File "C:\Program Files\WindowsApps\PythonSoftwareFoundation.Python.3.11_3.11.496.0_x64__qbz5n2kfra8p0\Lib\concurrent\futures\thread.py", line 58, in run
    result = self.fn(*self.args, **self.kwargs)
             ^^^^^^^^^^^^^^^^^^^^^^^^^^^^^^^^^^
  File "C:\Program Files\WindowsApps\PythonSoftwareFoundation.Python.3.11_3.11.496.0_x64__qbz5n2kfra8p0\Lib\pathlib.py", line 1013, in stat
    return os.stat(self, follow_symlinks=follow_symlinks)
           ^^^^^^^^^^^^^^^^^^^^^^^^^^^^^^^^^^^^^^^^^^^^^^
FileNotFoundError: [WinError 2] Не удается найти указанный файл: 'C:\\Users\\R\\PycharmProjects\\fastapi_admin\\src\\app\\modules\\bot\\routes\\demo.html'
2023-01-26 09:34:54,031 - ERROR - aiohttp.server - Unhandled exception
Traceback (most recent call last):
  File "C:\Users\R\PycharmProjects\fastapi_admin\venv\Lib\site-packages\aiohttp\web_protocol.py", line 512, in start
    resp, reset = await task
                  ^^^^^^^^^^
  File "C:\Users\R\PycharmProjects\fastapi_admin\venv\Lib\site-packages\aiohttp\web_protocol.py", line 458, in _handle_request
    reset = await self.finish_response(request, resp, start_time)
            ^^^^^^^^^^^^^^^^^^^^^^^^^^^^^^^^^^^^^^^^^^^^^^^^^^^^^
  File "C:\Users\R\PycharmProjects\fastapi_admin\venv\Lib\site-packages\aiohttp\web_protocol.py", line 611, in finish_response
    await prepare_meth(request)
  File "C:\Users\R\PycharmProjects\fastapi_admin\venv\Lib\site-packages\aiohttp\web_fileresponse.py", line 142, in prepare
    st: os.stat_result = await loop.run_in_executor(None, filepath.stat)
                         ^^^^^^^^^^^^^^^^^^^^^^^^^^^^^^^^^^^^^^^^^^^^^^^
  File "C:\Program Files\WindowsApps\PythonSoftwareFoundation.Python.3.11_3.11.496.0_x64__qbz5n2kfra8p0\Lib\concurrent\futures\thread.py", line 58, in run
    result = self.fn(*self.args, **self.kwargs)
             ^^^^^^^^^^^^^^^^^^^^^^^^^^^^^^^^^^
  File "C:\Program Files\WindowsApps\PythonSoftwareFoundation.Python.3.11_3.11.496.0_x64__qbz5n2kfra8p0\Lib\pathlib.py", line 1013, in stat
    return os.stat(self, follow_symlinks=follow_symlinks)
           ^^^^^^^^^^^^^^^^^^^^^^^^^^^^^^^^^^^^^^^^^^^^^^
FileNotFoundError: [WinError 2] Не удается найти указанный файл: 'C:\\Users\\R\\PycharmProjects\\fastapi_admin\\src\\app\\modules\\bot\\routes\\demo.html'
2023-01-26 09:34:54,047 - ERROR - aiohttp.server - Unhandled exception
Traceback (most recent call last):
  File "C:\Users\R\PycharmProjects\fastapi_admin\venv\Lib\site-packages\aiohttp\web_protocol.py", line 512, in start
    resp, reset = await task
                  ^^^^^^^^^^
  File "C:\Users\R\PycharmProjects\fastapi_admin\venv\Lib\site-packages\aiohttp\web_protocol.py", line 458, in _handle_request
    reset = await self.finish_response(request, resp, start_time)
            ^^^^^^^^^^^^^^^^^^^^^^^^^^^^^^^^^^^^^^^^^^^^^^^^^^^^^
  File "C:\Users\R\PycharmProjects\fastapi_admin\venv\Lib\site-packages\aiohttp\web_protocol.py", line 611, in finish_response
    await prepare_meth(request)
  File "C:\Users\R\PycharmProjects\fastapi_admin\venv\Lib\site-packages\aiohttp\web_fileresponse.py", line 142, in prepare
    st: os.stat_result = await loop.run_in_executor(None, filepath.stat)
                         ^^^^^^^^^^^^^^^^^^^^^^^^^^^^^^^^^^^^^^^^^^^^^^^
  File "C:\Program Files\WindowsApps\PythonSoftwareFoundation.Python.3.11_3.11.496.0_x64__qbz5n2kfra8p0\Lib\concurrent\futures\thread.py", line 58, in run
    result = self.fn(*self.args, **self.kwargs)
             ^^^^^^^^^^^^^^^^^^^^^^^^^^^^^^^^^^
  File "C:\Program Files\WindowsApps\PythonSoftwareFoundation.Python.3.11_3.11.496.0_x64__qbz5n2kfra8p0\Lib\pathlib.py", line 1013, in stat
    return os.stat(self, follow_symlinks=follow_symlinks)
           ^^^^^^^^^^^^^^^^^^^^^^^^^^^^^^^^^^^^^^^^^^^^^^
FileNotFoundError: [WinError 2] Не удается найти указанный файл: 'C:\\Users\\R\\PycharmProjects\\fastapi_admin\\src\\app\\modules\\bot\\routes\\demo.html'
2023-01-26 09:34:55,094 - ERROR - aiohttp.server - Unhandled exception
Traceback (most recent call last):
  File "C:\Users\R\PycharmProjects\fastapi_admin\venv\Lib\site-packages\aiohttp\web_protocol.py", line 512, in start
    resp, reset = await task
                  ^^^^^^^^^^
  File "C:\Users\R\PycharmProjects\fastapi_admin\venv\Lib\site-packages\aiohttp\web_protocol.py", line 458, in _handle_request
    reset = await self.finish_response(request, resp, start_time)
            ^^^^^^^^^^^^^^^^^^^^^^^^^^^^^^^^^^^^^^^^^^^^^^^^^^^^^
  File "C:\Users\R\PycharmProjects\fastapi_admin\venv\Lib\site-packages\aiohttp\web_protocol.py", line 611, in finish_response
    await prepare_meth(request)
  File "C:\Users\R\PycharmProjects\fastapi_admin\venv\Lib\site-packages\aiohttp\web_fileresponse.py", line 142, in prepare
    st: os.stat_result = await loop.run_in_executor(None, filepath.stat)
                         ^^^^^^^^^^^^^^^^^^^^^^^^^^^^^^^^^^^^^^^^^^^^^^^
  File "C:\Program Files\WindowsApps\PythonSoftwareFoundation.Python.3.11_3.11.496.0_x64__qbz5n2kfra8p0\Lib\concurrent\futures\thread.py", line 58, in run
    result = self.fn(*self.args, **self.kwargs)
             ^^^^^^^^^^^^^^^^^^^^^^^^^^^^^^^^^^
  File "C:\Program Files\WindowsApps\PythonSoftwareFoundation.Python.3.11_3.11.496.0_x64__qbz5n2kfra8p0\Lib\pathlib.py", line 1013, in stat
    return os.stat(self, follow_symlinks=follow_symlinks)
           ^^^^^^^^^^^^^^^^^^^^^^^^^^^^^^^^^^^^^^^^^^^^^^
FileNotFoundError: [WinError 2] Не удается найти указанный файл: 'C:\\Users\\R\\PycharmProjects\\fastapi_admin\\src\\app\\modules\\bot\\routes\\demo.html'
2023-01-26 09:34:55,108 - ERROR - aiohttp.server - Unhandled exception
Traceback (most recent call last):
  File "C:\Users\R\PycharmProjects\fastapi_admin\venv\Lib\site-packages\aiohttp\web_protocol.py", line 512, in start
    resp, reset = await task
                  ^^^^^^^^^^
  File "C:\Users\R\PycharmProjects\fastapi_admin\venv\Lib\site-packages\aiohttp\web_protocol.py", line 458, in _handle_request
    reset = await self.finish_response(request, resp, start_time)
            ^^^^^^^^^^^^^^^^^^^^^^^^^^^^^^^^^^^^^^^^^^^^^^^^^^^^^
  File "C:\Users\R\PycharmProjects\fastapi_admin\venv\Lib\site-packages\aiohttp\web_protocol.py", line 611, in finish_response
    await prepare_meth(request)
  File "C:\Users\R\PycharmProjects\fastapi_admin\venv\Lib\site-packages\aiohttp\web_fileresponse.py", line 142, in prepare
    st: os.stat_result = await loop.run_in_executor(None, filepath.stat)
                         ^^^^^^^^^^^^^^^^^^^^^^^^^^^^^^^^^^^^^^^^^^^^^^^
  File "C:\Program Files\WindowsApps\PythonSoftwareFoundation.Python.3.11_3.11.496.0_x64__qbz5n2kfra8p0\Lib\concurrent\futures\thread.py", line 58, in run
    result = self.fn(*self.args, **self.kwargs)
             ^^^^^^^^^^^^^^^^^^^^^^^^^^^^^^^^^^
  File "C:\Program Files\WindowsApps\PythonSoftwareFoundation.Python.3.11_3.11.496.0_x64__qbz5n2kfra8p0\Lib\pathlib.py", line 1013, in stat
    return os.stat(self, follow_symlinks=follow_symlinks)
           ^^^^^^^^^^^^^^^^^^^^^^^^^^^^^^^^^^^^^^^^^^^^^^
FileNotFoundError: [WinError 2] Не удается найти указанный файл: 'C:\\Users\\R\\PycharmProjects\\fastapi_admin\\src\\app\\modules\\bot\\routes\\demo.html'
2023-01-26 09:34:55,124 - ERROR - aiohttp.server - Unhandled exception
Traceback (most recent call last):
  File "C:\Users\R\PycharmProjects\fastapi_admin\venv\Lib\site-packages\aiohttp\web_protocol.py", line 512, in start
    resp, reset = await task
                  ^^^^^^^^^^
  File "C:\Users\R\PycharmProjects\fastapi_admin\venv\Lib\site-packages\aiohttp\web_protocol.py", line 458, in _handle_request
    reset = await self.finish_response(request, resp, start_time)
            ^^^^^^^^^^^^^^^^^^^^^^^^^^^^^^^^^^^^^^^^^^^^^^^^^^^^^
  File "C:\Users\R\PycharmProjects\fastapi_admin\venv\Lib\site-packages\aiohttp\web_protocol.py", line 611, in finish_response
    await prepare_meth(request)
  File "C:\Users\R\PycharmProjects\fastapi_admin\venv\Lib\site-packages\aiohttp\web_fileresponse.py", line 142, in prepare
    st: os.stat_result = await loop.run_in_executor(None, filepath.stat)
                         ^^^^^^^^^^^^^^^^^^^^^^^^^^^^^^^^^^^^^^^^^^^^^^^
  File "C:\Program Files\WindowsApps\PythonSoftwareFoundation.Python.3.11_3.11.496.0_x64__qbz5n2kfra8p0\Lib\concurrent\futures\thread.py", line 58, in run
    result = self.fn(*self.args, **self.kwargs)
             ^^^^^^^^^^^^^^^^^^^^^^^^^^^^^^^^^^
  File "C:\Program Files\WindowsApps\PythonSoftwareFoundation.Python.3.11_3.11.496.0_x64__qbz5n2kfra8p0\Lib\pathlib.py", line 1013, in stat
    return os.stat(self, follow_symlinks=follow_symlinks)
           ^^^^^^^^^^^^^^^^^^^^^^^^^^^^^^^^^^^^^^^^^^^^^^
FileNotFoundError: [WinError 2] Не удается найти указанный файл: 'C:\\Users\\R\\PycharmProjects\\fastapi_admin\\src\\app\\modules\\bot\\routes\\demo.html'
2023-01-26 09:35:00,173 - ERROR - aiohttp.server - Unhandled exception
Traceback (most recent call last):
  File "C:\Users\R\PycharmProjects\fastapi_admin\venv\Lib\site-packages\aiohttp\web_protocol.py", line 512, in start
    resp, reset = await task
                  ^^^^^^^^^^
  File "C:\Users\R\PycharmProjects\fastapi_admin\venv\Lib\site-packages\aiohttp\web_protocol.py", line 458, in _handle_request
    reset = await self.finish_response(request, resp, start_time)
            ^^^^^^^^^^^^^^^^^^^^^^^^^^^^^^^^^^^^^^^^^^^^^^^^^^^^^
  File "C:\Users\R\PycharmProjects\fastapi_admin\venv\Lib\site-packages\aiohttp\web_protocol.py", line 611, in finish_response
    await prepare_meth(request)
  File "C:\Users\R\PycharmProjects\fastapi_admin\venv\Lib\site-packages\aiohttp\web_fileresponse.py", line 142, in prepare
    st: os.stat_result = await loop.run_in_executor(None, filepath.stat)
                         ^^^^^^^^^^^^^^^^^^^^^^^^^^^^^^^^^^^^^^^^^^^^^^^
  File "C:\Program Files\WindowsApps\PythonSoftwareFoundation.Python.3.11_3.11.496.0_x64__qbz5n2kfra8p0\Lib\concurrent\futures\thread.py", line 58, in run
    result = self.fn(*self.args, **self.kwargs)
             ^^^^^^^^^^^^^^^^^^^^^^^^^^^^^^^^^^
  File "C:\Program Files\WindowsApps\PythonSoftwareFoundation.Python.3.11_3.11.496.0_x64__qbz5n2kfra8p0\Lib\pathlib.py", line 1013, in stat
    return os.stat(self, follow_symlinks=follow_symlinks)
           ^^^^^^^^^^^^^^^^^^^^^^^^^^^^^^^^^^^^^^^^^^^^^^
FileNotFoundError: [WinError 2] Не удается найти указанный файл: 'C:\\Users\\R\\PycharmProjects\\fastapi_admin\\src\\app\\modules\\bot\\routes\\demo.html'
2023-01-26 09:35:00,178 - ERROR - aiohttp.server - Unhandled exception
Traceback (most recent call last):
  File "C:\Users\R\PycharmProjects\fastapi_admin\venv\Lib\site-packages\aiohttp\web_protocol.py", line 512, in start
    resp, reset = await task
                  ^^^^^^^^^^
  File "C:\Users\R\PycharmProjects\fastapi_admin\venv\Lib\site-packages\aiohttp\web_protocol.py", line 458, in _handle_request
    reset = await self.finish_response(request, resp, start_time)
            ^^^^^^^^^^^^^^^^^^^^^^^^^^^^^^^^^^^^^^^^^^^^^^^^^^^^^
  File "C:\Users\R\PycharmProjects\fastapi_admin\venv\Lib\site-packages\aiohttp\web_protocol.py", line 611, in finish_response
    await prepare_meth(request)
  File "C:\Users\R\PycharmProjects\fastapi_admin\venv\Lib\site-packages\aiohttp\web_fileresponse.py", line 142, in prepare
    st: os.stat_result = await loop.run_in_executor(None, filepath.stat)
                         ^^^^^^^^^^^^^^^^^^^^^^^^^^^^^^^^^^^^^^^^^^^^^^^
  File "C:\Program Files\WindowsApps\PythonSoftwareFoundation.Python.3.11_3.11.496.0_x64__qbz5n2kfra8p0\Lib\concurrent\futures\thread.py", line 58, in run
    result = self.fn(*self.args, **self.kwargs)
             ^^^^^^^^^^^^^^^^^^^^^^^^^^^^^^^^^^
  File "C:\Program Files\WindowsApps\PythonSoftwareFoundation.Python.3.11_3.11.496.0_x64__qbz5n2kfra8p0\Lib\pathlib.py", line 1013, in stat
    return os.stat(self, follow_symlinks=follow_symlinks)
           ^^^^^^^^^^^^^^^^^^^^^^^^^^^^^^^^^^^^^^^^^^^^^^
FileNotFoundError: [WinError 2] Не удается найти указанный файл: 'C:\\Users\\R\\PycharmProjects\\fastapi_admin\\src\\app\\modules\\bot\\routes\\demo.html'
2023-01-26 09:35:00,185 - ERROR - aiohttp.server - Unhandled exception
Traceback (most recent call last):
  File "C:\Users\R\PycharmProjects\fastapi_admin\venv\Lib\site-packages\aiohttp\web_protocol.py", line 512, in start
    resp, reset = await task
                  ^^^^^^^^^^
  File "C:\Users\R\PycharmProjects\fastapi_admin\venv\Lib\site-packages\aiohttp\web_protocol.py", line 458, in _handle_request
    reset = await self.finish_response(request, resp, start_time)
            ^^^^^^^^^^^^^^^^^^^^^^^^^^^^^^^^^^^^^^^^^^^^^^^^^^^^^
  File "C:\Users\R\PycharmProjects\fastapi_admin\venv\Lib\site-packages\aiohttp\web_protocol.py", line 611, in finish_response
    await prepare_meth(request)
  File "C:\Users\R\PycharmProjects\fastapi_admin\venv\Lib\site-packages\aiohttp\web_fileresponse.py", line 142, in prepare
    st: os.stat_result = await loop.run_in_executor(None, filepath.stat)
                         ^^^^^^^^^^^^^^^^^^^^^^^^^^^^^^^^^^^^^^^^^^^^^^^
  File "C:\Program Files\WindowsApps\PythonSoftwareFoundation.Python.3.11_3.11.496.0_x64__qbz5n2kfra8p0\Lib\concurrent\futures\thread.py", line 58, in run
    result = self.fn(*self.args, **self.kwargs)
             ^^^^^^^^^^^^^^^^^^^^^^^^^^^^^^^^^^
  File "C:\Program Files\WindowsApps\PythonSoftwareFoundation.Python.3.11_3.11.496.0_x64__qbz5n2kfra8p0\Lib\pathlib.py", line 1013, in stat
    return os.stat(self, follow_symlinks=follow_symlinks)
           ^^^^^^^^^^^^^^^^^^^^^^^^^^^^^^^^^^^^^^^^^^^^^^
FileNotFoundError: [WinError 2] Не удается найти указанный файл: 'C:\\Users\\R\\PycharmProjects\\fastapi_admin\\src\\app\\modules\\bot\\routes\\demo.html'
2023-01-26 09:35:30,224 - ERROR - aiohttp.server - Unhandled exception
Traceback (most recent call last):
  File "C:\Users\R\PycharmProjects\fastapi_admin\venv\Lib\site-packages\aiohttp\web_protocol.py", line 512, in start
    resp, reset = await task
                  ^^^^^^^^^^
  File "C:\Users\R\PycharmProjects\fastapi_admin\venv\Lib\site-packages\aiohttp\web_protocol.py", line 458, in _handle_request
    reset = await self.finish_response(request, resp, start_time)
            ^^^^^^^^^^^^^^^^^^^^^^^^^^^^^^^^^^^^^^^^^^^^^^^^^^^^^
  File "C:\Users\R\PycharmProjects\fastapi_admin\venv\Lib\site-packages\aiohttp\web_protocol.py", line 611, in finish_response
    await prepare_meth(request)
  File "C:\Users\R\PycharmProjects\fastapi_admin\venv\Lib\site-packages\aiohttp\web_fileresponse.py", line 142, in prepare
    st: os.stat_result = await loop.run_in_executor(None, filepath.stat)
                         ^^^^^^^^^^^^^^^^^^^^^^^^^^^^^^^^^^^^^^^^^^^^^^^
  File "C:\Program Files\WindowsApps\PythonSoftwareFoundation.Python.3.11_3.11.496.0_x64__qbz5n2kfra8p0\Lib\concurrent\futures\thread.py", line 58, in run
    result = self.fn(*self.args, **self.kwargs)
             ^^^^^^^^^^^^^^^^^^^^^^^^^^^^^^^^^^
  File "C:\Program Files\WindowsApps\PythonSoftwareFoundation.Python.3.11_3.11.496.0_x64__qbz5n2kfra8p0\Lib\pathlib.py", line 1013, in stat
    return os.stat(self, follow_symlinks=follow_symlinks)
           ^^^^^^^^^^^^^^^^^^^^^^^^^^^^^^^^^^^^^^^^^^^^^^
FileNotFoundError: [WinError 2] Не удается найти указанный файл: 'C:\\Users\\R\\PycharmProjects\\fastapi_admin\\src\\app\\modules\\bot\\routes\\demo.html'
2023-01-26 09:35:30,231 - ERROR - aiohttp.server - Unhandled exception
Traceback (most recent call last):
  File "C:\Users\R\PycharmProjects\fastapi_admin\venv\Lib\site-packages\aiohttp\web_protocol.py", line 512, in start
    resp, reset = await task
                  ^^^^^^^^^^
  File "C:\Users\R\PycharmProjects\fastapi_admin\venv\Lib\site-packages\aiohttp\web_protocol.py", line 458, in _handle_request
    reset = await self.finish_response(request, resp, start_time)
            ^^^^^^^^^^^^^^^^^^^^^^^^^^^^^^^^^^^^^^^^^^^^^^^^^^^^^
  File "C:\Users\R\PycharmProjects\fastapi_admin\venv\Lib\site-packages\aiohttp\web_protocol.py", line 611, in finish_response
    await prepare_meth(request)
  File "C:\Users\R\PycharmProjects\fastapi_admin\venv\Lib\site-packages\aiohttp\web_fileresponse.py", line 142, in prepare
    st: os.stat_result = await loop.run_in_executor(None, filepath.stat)
                         ^^^^^^^^^^^^^^^^^^^^^^^^^^^^^^^^^^^^^^^^^^^^^^^
  File "C:\Program Files\WindowsApps\PythonSoftwareFoundation.Python.3.11_3.11.496.0_x64__qbz5n2kfra8p0\Lib\concurrent\futures\thread.py", line 58, in run
    result = self.fn(*self.args, **self.kwargs)
             ^^^^^^^^^^^^^^^^^^^^^^^^^^^^^^^^^^
  File "C:\Program Files\WindowsApps\PythonSoftwareFoundation.Python.3.11_3.11.496.0_x64__qbz5n2kfra8p0\Lib\pathlib.py", line 1013, in stat
    return os.stat(self, follow_symlinks=follow_symlinks)
           ^^^^^^^^^^^^^^^^^^^^^^^^^^^^^^^^^^^^^^^^^^^^^^
FileNotFoundError: [WinError 2] Не удается найти указанный файл: 'C:\\Users\\R\\PycharmProjects\\fastapi_admin\\src\\app\\modules\\bot\\routes\\demo.html'
2023-01-26 09:35:30,239 - ERROR - aiohttp.server - Unhandled exception
Traceback (most recent call last):
  File "C:\Users\R\PycharmProjects\fastapi_admin\venv\Lib\site-packages\aiohttp\web_protocol.py", line 512, in start
    resp, reset = await task
                  ^^^^^^^^^^
  File "C:\Users\R\PycharmProjects\fastapi_admin\venv\Lib\site-packages\aiohttp\web_protocol.py", line 458, in _handle_request
    reset = await self.finish_response(request, resp, start_time)
            ^^^^^^^^^^^^^^^^^^^^^^^^^^^^^^^^^^^^^^^^^^^^^^^^^^^^^
  File "C:\Users\R\PycharmProjects\fastapi_admin\venv\Lib\site-packages\aiohttp\web_protocol.py", line 611, in finish_response
    await prepare_meth(request)
  File "C:\Users\R\PycharmProjects\fastapi_admin\venv\Lib\site-packages\aiohttp\web_fileresponse.py", line 142, in prepare
    st: os.stat_result = await loop.run_in_executor(None, filepath.stat)
                         ^^^^^^^^^^^^^^^^^^^^^^^^^^^^^^^^^^^^^^^^^^^^^^^
  File "C:\Program Files\WindowsApps\PythonSoftwareFoundation.Python.3.11_3.11.496.0_x64__qbz5n2kfra8p0\Lib\concurrent\futures\thread.py", line 58, in run
    result = self.fn(*self.args, **self.kwargs)
             ^^^^^^^^^^^^^^^^^^^^^^^^^^^^^^^^^^
  File "C:\Program Files\WindowsApps\PythonSoftwareFoundation.Python.3.11_3.11.496.0_x64__qbz5n2kfra8p0\Lib\pathlib.py", line 1013, in stat
    return os.stat(self, follow_symlinks=follow_symlinks)
           ^^^^^^^^^^^^^^^^^^^^^^^^^^^^^^^^^^^^^^^^^^^^^^
FileNotFoundError: [WinError 2] Не удается найти указанный файл: 'C:\\Users\\R\\PycharmProjects\\fastapi_admin\\src\\app\\modules\\bot\\routes\\demo.html'
2023-01-26 09:41:20,987 - INFO - aiohttp.access - 127.0.0.1 [26/Jan/2023:06:41:20 +0000] "GET / HTTP/1.1" 404 173 "-" "Mozilla/5.0 (Windows NT 10.0; Win64; x64) AppleWebKit/537.36 (KHTML, like Gecko) Chrome/109.0.0.0 Safari/537.36"
2023-01-26 09:41:24,174 - INFO - aiohttp.access - 127.0.0.1 [26/Jan/2023:06:41:24 +0000] "GET /demo HTTP/1.1" 200 238 "-" "Mozilla/5.0 (Windows NT 10.0; Win64; x64) AppleWebKit/537.36 (KHTML, like Gecko) Chrome/109.0.0.0 Safari/537.36"
2023-01-26 09:41:43,392 - INFO - aiohttp.access - 127.0.0.1 [26/Jan/2023:06:41:43 +0000] "GET /demo?nextpage=1 HTTP/1.1" 200 238 "http://127.0.0.1:8081/demo" "Mozilla/5.0 (Windows NT 10.0; Win64; x64) AppleWebKit/537.36 (KHTML, like Gecko) Chrome/109.0.0.0 Safari/537.36"
2023-01-26 09:59:40,611 - INFO - aiogram.dispatcher - Start polling
2023-01-26 09:59:40,665 - INFO - aiogram.dispatcher - Run polling for bot @TestForALlProjectsBot id=5654331350 - 'TEST|BOT'
2023-01-26 09:59:48,230 - INFO - aiogram.event - Update id=859621605 is not handled. Duration 0 ms by bot id=5654331350
2023-01-26 09:59:48,231 - ERROR - aiogram.event - Cause exception while process update id=859621605 by bot id=5654331350
TypeError: command_webview() missing 1 required positional argument: 'base_url'
Traceback (most recent call last):
  File "C:\Users\R\PycharmProjects\fastapi_admin\venv\Lib\site-packages\aiogram\dispatcher\dispatcher.py", line 293, in _process_update
    response = await self.feed_update(bot, update, **kwargs)
               ^^^^^^^^^^^^^^^^^^^^^^^^^^^^^^^^^^^^^^^^^^^^^
  File "C:\Users\R\PycharmProjects\fastapi_admin\venv\Lib\site-packages\aiogram\dispatcher\dispatcher.py", line 142, in feed_update
    response = await self.update.wrap_outer_middleware(
               ^^^^^^^^^^^^^^^^^^^^^^^^^^^^^^^^^^^^^^^^
  File "C:\Users\R\PycharmProjects\fastapi_admin\venv\Lib\site-packages\aiogram\dispatcher\middlewares\error.py", line 25, in __call__
    return await handler(event, data)
           ^^^^^^^^^^^^^^^^^^^^^^^^^^
  File "C:\Users\R\PycharmProjects\fastapi_admin\venv\Lib\site-packages\aiogram\dispatcher\middlewares\user_context.py", line 23, in __call__
    return await handler(event, data)
           ^^^^^^^^^^^^^^^^^^^^^^^^^^
  File "C:\Program Files\WindowsApps\PythonSoftwareFoundation.Python.3.11_3.11.496.0_x64__qbz5n2kfra8p0\Lib\contextlib.py", line 222, in __aexit__
    await self.gen.athrow(typ, value, traceback)
  File "C:\Users\R\PycharmProjects\fastapi_admin\venv\Lib\site-packages\aiogram\fsm\storage\memory.py", line 52, in lock
    yield
  File "C:\Users\R\PycharmProjects\fastapi_admin\venv\Lib\site-packages\aiogram\fsm\middleware.py", line 34, in __call__
    return await handler(event, data)
           ^^^^^^^^^^^^^^^^^^^^^^^^^^
  File "C:\Users\R\PycharmProjects\fastapi_admin\venv\Lib\site-packages\aiogram\dispatcher\event\telegram.py", line 111, in trigger
    return await wrapped_inner(event, kwargs)
           ^^^^^^^^^^^^^^^^^^^^^^^^^^^^^^^^^^
  File "C:\Users\R\PycharmProjects\fastapi_admin\venv\Lib\site-packages\aiogram\dispatcher\event\handler.py", line 42, in call
    return await wrapped()
           ^^^^^^^^^^^^^^^
  File "C:\Users\R\PycharmProjects\fastapi_admin\venv\Lib\site-packages\aiogram\dispatcher\dispatcher.py", line 260, in _listen_update
    return await self.propagate_event(update_type=update_type, event=event, **kwargs)
           ^^^^^^^^^^^^^^^^^^^^^^^^^^^^^^^^^^^^^^^^^^^^^^^^^^^^^^^^^^^^^^^^^^^^^^^^^^
  File "C:\Users\R\PycharmProjects\fastapi_admin\venv\Lib\site-packages\aiogram\dispatcher\router.py", line 115, in propagate_event
    return await observer.wrap_outer_middleware(_wrapped, event=event, data=kwargs)
           ^^^^^^^^^^^^^^^^^^^^^^^^^^^^^^^^^^^^^^^^^^^^^^^^^^^^^^^^^^^^^^^^^^^^^^^^
  File "C:\Users\R\PycharmProjects\fastapi_admin\venv\Lib\site-packages\aiogram\dispatcher\router.py", line 111, in _wrapped
    return await self._propagate_event(
           ^^^^^^^^^^^^^^^^^^^^^^^^^^^^
  File "C:\Users\R\PycharmProjects\fastapi_admin\venv\Lib\site-packages\aiogram\dispatcher\router.py", line 131, in _propagate_event
    response = await router.propagate_event(update_type=update_type, event=event, **kwargs)
               ^^^^^^^^^^^^^^^^^^^^^^^^^^^^^^^^^^^^^^^^^^^^^^^^^^^^^^^^^^^^^^^^^^^^^^^^^^^^
  File "C:\Users\R\PycharmProjects\fastapi_admin\venv\Lib\site-packages\aiogram\dispatcher\router.py", line 115, in propagate_event
    return await observer.wrap_outer_middleware(_wrapped, event=event, data=kwargs)
           ^^^^^^^^^^^^^^^^^^^^^^^^^^^^^^^^^^^^^^^^^^^^^^^^^^^^^^^^^^^^^^^^^^^^^^^^
  File "C:\Users\R\PycharmProjects\fastapi_admin\venv\Lib\site-packages\aiogram\dispatcher\router.py", line 111, in _wrapped
    return await self._propagate_event(
           ^^^^^^^^^^^^^^^^^^^^^^^^^^^^
  File "C:\Users\R\PycharmProjects\fastapi_admin\venv\Lib\site-packages\aiogram\dispatcher\router.py", line 124, in _propagate_event
    response = await observer.trigger(event, **kwargs)
               ^^^^^^^^^^^^^^^^^^^^^^^^^^^^^^^^^^^^^^^
  File "C:\Users\R\PycharmProjects\fastapi_admin\venv\Lib\site-packages\aiogram\dispatcher\event\telegram.py", line 111, in trigger
    return await wrapped_inner(event, kwargs)
           ^^^^^^^^^^^^^^^^^^^^^^^^^^^^^^^^^^
  File "C:\Users\R\PycharmProjects\fastapi_admin\venv\Lib\site-packages\aiogram\dispatcher\event\handler.py", line 42, in call
    return await wrapped()
                 ^^^^^^^^^
TypeError: command_webview() missing 1 required positional argument: 'base_url'
2023-01-26 10:00:41,451 - INFO - aiogram.dispatcher - Polling stopped
2023-01-26 10:00:43,081 - INFO - aiogram.dispatcher - Start polling
2023-01-26 10:00:43,131 - INFO - aiogram.dispatcher - Run polling for bot @TestForALlProjectsBot id=5654331350 - 'TEST|BOT'
2023-01-26 10:00:46,318 - INFO - aiogram.event - Update id=859621606 is handled. Duration 186 ms by bot id=5654331350
2023-01-26 10:00:52,000 - INFO - aiogram.dispatcher - Polling stopped
2023-01-26 10:01:24,370 - INFO - aiogram.dispatcher - Start polling
2023-01-26 10:01:24,422 - INFO - aiogram.dispatcher - Run polling for bot @TestForALlProjectsBot id=5654331350 - 'TEST|BOT'
2023-01-26 10:01:26,206 - INFO - aiogram.event - Update id=859621607 is handled. Duration 250 ms by bot id=5654331350
2023-01-26 10:01:31,447 - INFO - aiogram.dispatcher - Polling stopped
2023-01-26 10:01:46,837 - INFO - aiogram.dispatcher - Start polling
2023-01-26 10:01:46,892 - INFO - aiogram.dispatcher - Run polling for bot @TestForALlProjectsBot id=5654331350 - 'TEST|BOT'
2023-01-26 10:01:48,237 - INFO - aiogram.event - Update id=859621608 is handled. Duration 406 ms by bot id=5654331350
2023-01-26 10:01:52,009 - INFO - aiogram.dispatcher - Polling stopped
2023-01-26 10:02:16,119 - INFO - aiogram.dispatcher - Start polling
2023-01-26 10:02:16,172 - INFO - aiogram.dispatcher - Run polling for bot @TestForALlProjectsBot id=5654331350 - 'TEST|BOT'
2023-01-26 10:02:19,614 - INFO - aiogram.dispatcher - Polling stopped
2023-01-26 10:02:36,122 - INFO - aiogram.dispatcher - Start polling
2023-01-26 10:02:36,175 - INFO - aiogram.dispatcher - Run polling for bot @TestForALlProjectsBot id=5654331350 - 'TEST|BOT'
2023-01-26 10:02:42,895 - INFO - aiogram.event - Update id=859621609 is not handled. Duration 172 ms by bot id=5654331350
2023-01-26 10:02:42,896 - ERROR - aiogram.event - Cause exception while process update id=859621609 by bot id=5654331350
TelegramBadRequest: Bad Request: inline keyboard button Web App URL 'http://127.0.0.1//demo' is invalid: Only HTTPS links are allowed
Traceback (most recent call last):
  File "C:\Users\R\PycharmProjects\fastapi_admin\venv\Lib\site-packages\aiogram\dispatcher\dispatcher.py", line 293, in _process_update
    response = await self.feed_update(bot, update, **kwargs)
               ^^^^^^^^^^^^^^^^^^^^^^^^^^^^^^^^^^^^^^^^^^^^^
  File "C:\Users\R\PycharmProjects\fastapi_admin\venv\Lib\site-packages\aiogram\dispatcher\dispatcher.py", line 142, in feed_update
    response = await self.update.wrap_outer_middleware(
               ^^^^^^^^^^^^^^^^^^^^^^^^^^^^^^^^^^^^^^^^
  File "C:\Users\R\PycharmProjects\fastapi_admin\venv\Lib\site-packages\aiogram\dispatcher\middlewares\error.py", line 25, in __call__
    return await handler(event, data)
           ^^^^^^^^^^^^^^^^^^^^^^^^^^
  File "C:\Users\R\PycharmProjects\fastapi_admin\venv\Lib\site-packages\aiogram\dispatcher\middlewares\user_context.py", line 23, in __call__
    return await handler(event, data)
           ^^^^^^^^^^^^^^^^^^^^^^^^^^
  File "C:\Program Files\WindowsApps\PythonSoftwareFoundation.Python.3.11_3.11.496.0_x64__qbz5n2kfra8p0\Lib\contextlib.py", line 222, in __aexit__
    await self.gen.athrow(typ, value, traceback)
  File "C:\Users\R\PycharmProjects\fastapi_admin\venv\Lib\site-packages\aiogram\fsm\storage\memory.py", line 52, in lock
    yield
  File "C:\Users\R\PycharmProjects\fastapi_admin\venv\Lib\site-packages\aiogram\fsm\middleware.py", line 34, in __call__
    return await handler(event, data)
           ^^^^^^^^^^^^^^^^^^^^^^^^^^
  File "C:\Users\R\PycharmProjects\fastapi_admin\venv\Lib\site-packages\aiogram\dispatcher\event\telegram.py", line 111, in trigger
    return await wrapped_inner(event, kwargs)
           ^^^^^^^^^^^^^^^^^^^^^^^^^^^^^^^^^^
  File "C:\Users\R\PycharmProjects\fastapi_admin\venv\Lib\site-packages\aiogram\dispatcher\event\handler.py", line 42, in call
    return await wrapped()
           ^^^^^^^^^^^^^^^
  File "C:\Users\R\PycharmProjects\fastapi_admin\venv\Lib\site-packages\aiogram\dispatcher\dispatcher.py", line 260, in _listen_update
    return await self.propagate_event(update_type=update_type, event=event, **kwargs)
           ^^^^^^^^^^^^^^^^^^^^^^^^^^^^^^^^^^^^^^^^^^^^^^^^^^^^^^^^^^^^^^^^^^^^^^^^^^
  File "C:\Users\R\PycharmProjects\fastapi_admin\venv\Lib\site-packages\aiogram\dispatcher\router.py", line 115, in propagate_event
    return await observer.wrap_outer_middleware(_wrapped, event=event, data=kwargs)
           ^^^^^^^^^^^^^^^^^^^^^^^^^^^^^^^^^^^^^^^^^^^^^^^^^^^^^^^^^^^^^^^^^^^^^^^^
  File "C:\Users\R\PycharmProjects\fastapi_admin\venv\Lib\site-packages\aiogram\dispatcher\router.py", line 111, in _wrapped
    return await self._propagate_event(
           ^^^^^^^^^^^^^^^^^^^^^^^^^^^^
  File "C:\Users\R\PycharmProjects\fastapi_admin\venv\Lib\site-packages\aiogram\dispatcher\router.py", line 131, in _propagate_event
    response = await router.propagate_event(update_type=update_type, event=event, **kwargs)
               ^^^^^^^^^^^^^^^^^^^^^^^^^^^^^^^^^^^^^^^^^^^^^^^^^^^^^^^^^^^^^^^^^^^^^^^^^^^^
  File "C:\Users\R\PycharmProjects\fastapi_admin\venv\Lib\site-packages\aiogram\dispatcher\router.py", line 115, in propagate_event
    return await observer.wrap_outer_middleware(_wrapped, event=event, data=kwargs)
           ^^^^^^^^^^^^^^^^^^^^^^^^^^^^^^^^^^^^^^^^^^^^^^^^^^^^^^^^^^^^^^^^^^^^^^^^
  File "C:\Users\R\PycharmProjects\fastapi_admin\venv\Lib\site-packages\aiogram\dispatcher\router.py", line 111, in _wrapped
    return await self._propagate_event(
           ^^^^^^^^^^^^^^^^^^^^^^^^^^^^
  File "C:\Users\R\PycharmProjects\fastapi_admin\venv\Lib\site-packages\aiogram\dispatcher\router.py", line 124, in _propagate_event
    response = await observer.trigger(event, **kwargs)
               ^^^^^^^^^^^^^^^^^^^^^^^^^^^^^^^^^^^^^^^
  File "C:\Users\R\PycharmProjects\fastapi_admin\venv\Lib\site-packages\aiogram\dispatcher\event\telegram.py", line 111, in trigger
    return await wrapped_inner(event, kwargs)
           ^^^^^^^^^^^^^^^^^^^^^^^^^^^^^^^^^^
  File "C:\Users\R\PycharmProjects\fastapi_admin\venv\Lib\site-packages\aiogram\dispatcher\event\handler.py", line 42, in call
    return await wrapped()
           ^^^^^^^^^^^^^^^
  File "C:\Users\R\PycharmProjects\fastapi_admin\src\app\modules\bot\handlers\start.py", line 25, in command_webview
    await message.answer(
  File "C:\Users\R\PycharmProjects\fastapi_admin\venv\Lib\site-packages\aiogram\methods\base.py", line 86, in emit
    return await bot(self)
           ^^^^^^^^^^^^^^^
  File "C:\Users\R\PycharmProjects\fastapi_admin\venv\Lib\site-packages\aiogram\client\bot.py", line 364, in __call__
    return await self.session(self, method, timeout=request_timeout)
           ^^^^^^^^^^^^^^^^^^^^^^^^^^^^^^^^^^^^^^^^^^^^^^^^^^^^^^^^^
  File "C:\Users\R\PycharmProjects\fastapi_admin\venv\Lib\site-packages\aiogram\client\session\base.py", line 182, in __call__
    return cast(TelegramType, await middleware(bot, method))
                              ^^^^^^^^^^^^^^^^^^^^^^^^^^^^^
  File "C:\Users\R\PycharmProjects\fastapi_admin\venv\Lib\site-packages\aiogram\client\session\aiohttp.py", line 157, in make_request
    response = self.check_response(method=method, status_code=resp.status, content=raw_result)
               ^^^^^^^^^^^^^^^^^^^^^^^^^^^^^^^^^^^^^^^^^^^^^^^^^^^^^^^^^^^^^^^^^^^^^^^^^^^^^^^
  File "C:\Users\R\PycharmProjects\fastapi_admin\venv\Lib\site-packages\aiogram\client\session\base.py", line 100, in check_response
    raise TelegramBadRequest(method=method, message=description)
aiogram.exceptions.TelegramBadRequest: Bad Request: inline keyboard button Web App URL 'http://127.0.0.1//demo' is invalid: Only HTTPS links are allowed
2023-01-26 10:02:55,693 - INFO - aiogram.dispatcher - Polling stopped
2023-01-26 10:02:57,336 - INFO - aiogram.dispatcher - Start polling
2023-01-26 10:02:57,389 - INFO - aiogram.dispatcher - Run polling for bot @TestForALlProjectsBot id=5654331350 - 'TEST|BOT'
2023-01-26 10:02:58,336 - INFO - aiogram.event - Update id=859621610 is handled. Duration 218 ms by bot id=5654331350
2023-01-26 10:03:08,262 - INFO - aiogram.dispatcher - Polling stopped
2023-02-10 22:58:34,831 - INFO - aiogram.dispatcher - Start polling
2023-02-10 22:58:34,888 - INFO - aiogram.dispatcher - Run polling for bot @TestForALlProjectsBot id=5654331350 - 'TEST|BOT'
2023-02-10 22:58:41,184 - INFO - aiogram.event - Update id=859621833 is not handled. Duration 187 ms by bot id=5654331350
2023-02-10 22:58:41,185 - ERROR - aiogram.event - Cause exception while process update id=859621833 by bot id=5654331350
TelegramBadRequest: Bad Request: menu button Web App URL 'localhost/demo' is invalid: Only HTTPS links are allowed
Traceback (most recent call last):
  File "C:\Users\R\PycharmProjects\fastapi-admin\venv\Lib\site-packages\aiogram\dispatcher\dispatcher.py", line 293, in _process_update
    response = await self.feed_update(bot, update, **kwargs)
               ^^^^^^^^^^^^^^^^^^^^^^^^^^^^^^^^^^^^^^^^^^^^^
  File "C:\Users\R\PycharmProjects\fastapi-admin\venv\Lib\site-packages\aiogram\dispatcher\dispatcher.py", line 142, in feed_update
    response = await self.update.wrap_outer_middleware(
               ^^^^^^^^^^^^^^^^^^^^^^^^^^^^^^^^^^^^^^^^
  File "C:\Users\R\PycharmProjects\fastapi-admin\venv\Lib\site-packages\aiogram\dispatcher\middlewares\error.py", line 25, in __call__
    return await handler(event, data)
           ^^^^^^^^^^^^^^^^^^^^^^^^^^
  File "C:\Users\R\PycharmProjects\fastapi-admin\venv\Lib\site-packages\aiogram\dispatcher\middlewares\user_context.py", line 23, in __call__
    return await handler(event, data)
           ^^^^^^^^^^^^^^^^^^^^^^^^^^
  File "C:\Program Files\WindowsApps\PythonSoftwareFoundation.Python.3.11_3.11.496.0_x64__qbz5n2kfra8p0\Lib\contextlib.py", line 222, in __aexit__
    await self.gen.athrow(typ, value, traceback)
  File "C:\Users\R\PycharmProjects\fastapi-admin\venv\Lib\site-packages\aiogram\fsm\storage\memory.py", line 52, in lock
    yield
  File "C:\Users\R\PycharmProjects\fastapi-admin\venv\Lib\site-packages\aiogram\fsm\middleware.py", line 34, in __call__
    return await handler(event, data)
           ^^^^^^^^^^^^^^^^^^^^^^^^^^
  File "C:\Users\R\PycharmProjects\fastapi-admin\venv\Lib\site-packages\aiogram\dispatcher\event\telegram.py", line 111, in trigger
    return await wrapped_inner(event, kwargs)
           ^^^^^^^^^^^^^^^^^^^^^^^^^^^^^^^^^^
  File "C:\Users\R\PycharmProjects\fastapi-admin\venv\Lib\site-packages\aiogram\dispatcher\event\handler.py", line 42, in call
    return await wrapped()
           ^^^^^^^^^^^^^^^
  File "C:\Users\R\PycharmProjects\fastapi-admin\venv\Lib\site-packages\aiogram\dispatcher\dispatcher.py", line 260, in _listen_update
    return await self.propagate_event(update_type=update_type, event=event, **kwargs)
           ^^^^^^^^^^^^^^^^^^^^^^^^^^^^^^^^^^^^^^^^^^^^^^^^^^^^^^^^^^^^^^^^^^^^^^^^^^
  File "C:\Users\R\PycharmProjects\fastapi-admin\venv\Lib\site-packages\aiogram\dispatcher\router.py", line 115, in propagate_event
    return await observer.wrap_outer_middleware(_wrapped, event=event, data=kwargs)
           ^^^^^^^^^^^^^^^^^^^^^^^^^^^^^^^^^^^^^^^^^^^^^^^^^^^^^^^^^^^^^^^^^^^^^^^^
  File "C:\Users\R\PycharmProjects\fastapi-admin\venv\Lib\site-packages\aiogram\dispatcher\router.py", line 111, in _wrapped
    return await self._propagate_event(
           ^^^^^^^^^^^^^^^^^^^^^^^^^^^^
  File "C:\Users\R\PycharmProjects\fastapi-admin\venv\Lib\site-packages\aiogram\dispatcher\router.py", line 131, in _propagate_event
    response = await router.propagate_event(update_type=update_type, event=event, **kwargs)
               ^^^^^^^^^^^^^^^^^^^^^^^^^^^^^^^^^^^^^^^^^^^^^^^^^^^^^^^^^^^^^^^^^^^^^^^^^^^^
  File "C:\Users\R\PycharmProjects\fastapi-admin\venv\Lib\site-packages\aiogram\dispatcher\router.py", line 115, in propagate_event
    return await observer.wrap_outer_middleware(_wrapped, event=event, data=kwargs)
           ^^^^^^^^^^^^^^^^^^^^^^^^^^^^^^^^^^^^^^^^^^^^^^^^^^^^^^^^^^^^^^^^^^^^^^^^
  File "C:\Users\R\PycharmProjects\fastapi-admin\venv\Lib\site-packages\aiogram\dispatcher\router.py", line 111, in _wrapped
    return await self._propagate_event(
           ^^^^^^^^^^^^^^^^^^^^^^^^^^^^
  File "C:\Users\R\PycharmProjects\fastapi-admin\venv\Lib\site-packages\aiogram\dispatcher\router.py", line 124, in _propagate_event
    response = await observer.trigger(event, **kwargs)
               ^^^^^^^^^^^^^^^^^^^^^^^^^^^^^^^^^^^^^^^
  File "C:\Users\R\PycharmProjects\fastapi-admin\venv\Lib\site-packages\aiogram\dispatcher\event\telegram.py", line 111, in trigger
    return await wrapped_inner(event, kwargs)
           ^^^^^^^^^^^^^^^^^^^^^^^^^^^^^^^^^^
  File "C:\Users\R\PycharmProjects\fastapi-admin\venv\Lib\site-packages\aiogram\dispatcher\event\handler.py", line 42, in call
    return await wrapped()
           ^^^^^^^^^^^^^^^
  File "C:\Users\R\PycharmProjects\fastapi-admin\backend\bot\handlers\start.py", line 15, in command_start
    await bot.set_chat_menu_button(
  File "C:\Users\R\PycharmProjects\fastapi-admin\venv\Lib\site-packages\aiogram\client\bot.py", line 2603, in set_chat_menu_button
    return await self(call, request_timeout=request_timeout)
           ^^^^^^^^^^^^^^^^^^^^^^^^^^^^^^^^^^^^^^^^^^^^^^^^^
  File "C:\Users\R\PycharmProjects\fastapi-admin\venv\Lib\site-packages\aiogram\client\bot.py", line 364, in __call__
    return await self.session(self, method, timeout=request_timeout)
           ^^^^^^^^^^^^^^^^^^^^^^^^^^^^^^^^^^^^^^^^^^^^^^^^^^^^^^^^^
  File "C:\Users\R\PycharmProjects\fastapi-admin\venv\Lib\site-packages\aiogram\client\session\base.py", line 182, in __call__
    return cast(TelegramType, await middleware(bot, method))
                              ^^^^^^^^^^^^^^^^^^^^^^^^^^^^^
  File "C:\Users\R\PycharmProjects\fastapi-admin\venv\Lib\site-packages\aiogram\client\session\aiohttp.py", line 157, in make_request
    response = self.check_response(method=method, status_code=resp.status, content=raw_result)
               ^^^^^^^^^^^^^^^^^^^^^^^^^^^^^^^^^^^^^^^^^^^^^^^^^^^^^^^^^^^^^^^^^^^^^^^^^^^^^^^
  File "C:\Users\R\PycharmProjects\fastapi-admin\venv\Lib\site-packages\aiogram\client\session\base.py", line 100, in check_response
    raise TelegramBadRequest(method=method, message=description)
aiogram.exceptions.TelegramBadRequest: Bad Request: menu button Web App URL 'localhost/demo' is invalid: Only HTTPS links are allowed
2023-02-10 22:58:48,841 - INFO - aiogram.dispatcher - Polling stopped
2023-02-10 22:59:26,173 - INFO - aiogram.dispatcher - Start polling
2023-02-10 22:59:26,362 - INFO - aiogram.dispatcher - Run polling for bot @TestForALlProjectsBot id=5654331350 - 'TEST|BOT'
2023-02-10 22:59:28,188 - INFO - aiogram.event - Update id=859621834 is handled. Duration 641 ms by bot id=5654331350
2023-02-10 23:02:48,550 - INFO - aiogram.dispatcher - Polling stopped
2023-02-10 23:40:06,293 - INFO - aiogram.dispatcher - Start polling
2023-02-10 23:40:06,346 - INFO - aiogram.dispatcher - Run polling for bot @TestForALlProjectsBot id=5654331350 - 'TEST|BOT'
2023-02-10 23:40:09,973 - INFO - aiogram.dispatcher - Polling stopped
